<mujoco model="a1z_tabletop">
  <compiler angle="radian" meshdir="assets" />
  <option timestep="0.002" gravity="0 0 -9.81" integrator="implicitfast" />
  <asset>
    <mesh name="arm_link1.STL" file="arm_link1.STL" />
    <mesh name="arm_link2.STL" file="arm_link2.STL" />
    <mesh name="arm_link3.STL" file="arm_link3.STL" />
    <mesh name="arm_link4.STL" file="arm_link4.STL" />
    <mesh name="arm_link5.STL" file="arm_link5.STL" />
    <mesh name="arm_link6.STL" file="arm_link6.STL" />
    <mesh name="base_link.STL" file="base_link.STL" />
    <mesh name="gripper_finger_left_link.STL" file="gripper_finger_left_link.STL" />
    <mesh name="gripper_finger_rIght_link.STL" file="gripper_finger_rIght_link.STL" />
    <texture name="cube_texture" type="2d" builtin="flat" width="32" height="32" rgb1="0.9 0.2 0.05" rgb2="0.9 0.2 0.05" />
    <material name="cube_material" texture="cube_texture" />
  </asset>
  <worldbody>
    <light name="key_light" pos="1 -1 2.5" dir="-0.3 0.3 -1" directional="true" />
    <body name="table" pos="0 0 0.38">
      <geom name="tabletop" type="box" size="0.65 0.5 0.03" pos="0 0 0" friction="0.8 0.1 0.1" />
      <geom name="table_leg" type="box" size="0.05 0.05 0.38" pos="-0.5 0  -0.38" />
    </body>
    <body name="a1z" pos="0.42 0 0.41">
      <body name="base_link">
        <geom name="base_link_visual" type="mesh" mesh="base_link.STL" contype="0" conaffinity="0" mass="0.1" />
        <body name="arm_link1" pos="0 0 0.075" euler="0 0 0">
          <joint name="arm_joint1" type="hinge" damping="1" axis="0 0 1" range="-2.094 2.094" />
          <geom name="arm_link1_visual" type="mesh" mesh="arm_link1.STL" contype="0" conaffinity="0" mass="0.1" />
          <body name="arm_link2" pos="0.02 0 0.043" euler="0 0 0">
            <joint name="arm_joint2" type="hinge" damping="1" axis="0 1 0" range="0 3.142" />
            <geom name="arm_link2_visual" type="mesh" mesh="arm_link2.STL" contype="0" conaffinity="0" mass="0.1" />
            <body name="arm_link3" pos="-0.264 0 0" euler="0 0 0">
              <joint name="arm_joint3" type="hinge" damping="1" axis="0 1 0" range="-3.142 0" />
              <geom name="arm_link3_visual" type="mesh" mesh="arm_link3.STL" contype="0" conaffinity="0" mass="0.1" />
              <body name="arm_link4" pos="0.245 0 0.06" euler="0 0 0">
                <joint name="arm_joint4" type="hinge" damping="1" axis="0 1 0" range="-1.309 1.309" />
                <geom name="arm_link4_visual" type="mesh" mesh="arm_link4.STL" contype="0" conaffinity="0" mass="0.1" />
                <body name="arm_link5" pos="0.074 0 0.042" euler="0 0 0">
                  <joint name="arm_joint5" type="hinge" damping="1" axis="0 0 1" range="-1.484 1.484" />
                  <geom name="arm_link5_visual" type="mesh" mesh="arm_link5.STL" contype="0" conaffinity="0" mass="0.1" />
                  <body name="arm_link6" pos="0.0235 0 -0.042" euler="0 0 0">
                    <joint name="arm_joint6" type="hinge" damping="1" axis="1 0 0" range="-2.007 2.007" />
                    <geom name="arm_link6_visual" type="mesh" mesh="arm_link6.STL" contype="0" conaffinity="0" mass="0.1" />
                    <body name="gripper_finger_left_link" pos="0.0727 -0.025 0.018" euler="0 0 0">
                      <joint name="gripper_finger_left_joint" type="slide" damping="1" axis="0 -0.811 0.584" range="0 0.015" />
                      <geom name="gripper_finger_left_link_visual" type="mesh" mesh="gripper_finger_left_link.STL" contype="0" conaffinity="0" mass="0.1" />
                      <geom name="left_pad" type="box" size="0.025 0.004 0.012" pos="0.105 0 0" friction="0.8 0.1 0.1" />
                    </body>
                    <body name="gripper_finger_rIght_link" pos="0.0727 0.025 -0.018" euler="0 0 0">
                      <joint name="gripper_finger_rIght_joint" type="slide" damping="1" axis="0 0.811 -0.584" range="0 0.015" />
                      <geom name="gripper_finger_rIght_link_visual" type="mesh" mesh="gripper_finger_rIght_link.STL" contype="0" conaffinity="0" mass="0.1" />
                      <geom name="right_pad" type="box" size="0.025 0.004 0.012" pos="0.105 0 0" friction="0.8 0.1 0.1" />
                    </body>
                    <body name="gripper_eef_link" pos="0.0727 0 0" euler="0 0 0" />
                    <camera name="wrist_camera" pos="0.11 0 -0.02" euler="0 1.57 1.57" mode="fixed" fovy="65" />
                  </body>
                </body>
              </body>
            </body>
          </body>
        </body>
      </body>
    </body>
    <body name="cube" pos="0.08 -0.05 0.46">
      <freejoint name="cube_free" />
      <geom name="cube_geom" type="box" size="0.025 0.025 0.025" mass="0.1" material="cube_material" friction="0.8 0.1 0.1" />
    </body>
  </worldbody>
  <actuator>
    <position name="arm_joint1_motor" joint="arm_joint1" kp="500.0" kv="45.0" />
    <position name="arm_joint2_motor" joint="arm_joint2" kp="500.0" kv="45.0" />
    <position name="arm_joint3_motor" joint="arm_joint3" kp="500.0" kv="45.0" />
    <position name="arm_joint4_motor" joint="arm_joint4" kp="500.0" kv="45.0" />
    <position name="arm_joint5_motor" joint="arm_joint5" kp="500.0" kv="45.0" />
    <position name="arm_joint6_motor" joint="arm_joint6" kp="500.0" kv="45.0" />
    <position name="gripper_motor" joint="gripper_finger_left_joint" kp="10" kv="5" ctrlrange="0 0.015" />
  </actuator>
  <equality>
    <joint name="gripper_mimic" joint1="gripper_finger_rIght_joint" joint2="gripper_finger_left_joint" polycoef="0 1 0 0 0" />
  </equality>
  <visual>
    <global offwidth="640" offheight="480" />
  </visual>
  <custom>
    <numeric name="wrist_camera_fps" data="30" />
  </custom>
  <keyframe>
    <key name="home" qpos="0.0 0.7 -1.2 0.5 0.0 0.0 0.0 0.0 0.08 -0.05 0.46 1.0 0.0 0.0 0.0" />
  </keyframe>
</mujoco>
